Workbook

Sheet Test Cases
A1: Sauce Demo – UI Test Case Repository
A2: TC ID | B2: Module | C2: Page/Screen | D2: User Action | E2: Test Scenario | F2: Test Type | G2: Preconditions | H2: Steps | I2: Expected Result | J2: Priority | K2: Status
A3: LOGIN
A4: TC-001 | B4: Login | C4: Login Page | D4: Login | E4: Valid login | F4: Functional | G4: Browser open, on login page | H4: 1. Enter username (standard_user) and password (secret_sauce) 2. Click Login. | I4: User is redirected to Products page, 6 items listed. | J4: High | K4: Passed
A5: TC-002 | B5: Login | C5: Login Page | D5: Login | E5: Locked out user | F5: Negative | G5: On login page | H5: 1. Enter username (locked_out_user) and password (secret_sauce 2. Click Login | I5: Error: 'Epic sadface: Sorry, this user has been locked out.'; user stays on login page. | J5: High | K5: Passed
A6: TC-003 | B6: Login | C6: Login Page | D6: Login | E6: Invalid credentials | F6: Negative | G6: On login page | H6: 1. Enter made-up username/password 2. Click Login | I6: Error: 'Epic sadface: Username and password do not match any user in this service' | J6: High | K6: Passed
A7: TC-004 | B7: Login | C7: Login Page | D7: Login | E7: Empty username | F7: Negative | G7: On login page | H7: 1. Leave username blank 2. Enter any password 3. Click Login | I7: Error: 'Epic sadface: Username is required' | J7: Medium | K7: Passed
A8: TC-005 | B8: Login | C8: Login Page | D8: Login | E8: Empty password | F8: Negative | G8: On login page | H8: 1. Enter valid username 2. Leave password blank 3. Click Login | I8: Error: 'Epic sadface: Password is required' | J8: Medium | K8: Passed
A9: TC-006 | B9: Login | C9: Login Page | D9: Login | E9: Both fields empty | F9: Negative | G9: On login page | H9: 1. Leave both fields blank 2. Click Login | I9: Error: 'Epic sadface: Username is required' (validated first) | J9: Low | K9: Passed
A10: TC-007 | B10: Login | C10: Login Page | D10: Login | E10: Login with problem_user | F10: Bug validation | G10: On login page | H10: 1. Enter username (problem_user) and password (secret_sauce) 2. Click Login | I10: Login succeeds; reaches Products page. Record any visual defects for later cases | J10: Medium | K10: Passed
A11: TC-008 | B11: Login | C11: Login Page | D11: Login | E11: Login with performance_glitch_user | F11: Bug validation | G11: On login page | H11: 1. Enter username (performance_glitch_user) and password (secret_sauce) 2. Click Login | I11: Login eventually succeeds with a noticeable delay vs. standard_user | J11: Low | K11: Passed
A12: TC-009 | B12: Login | C12: Login Page | D12: Login | E12: Dismiss error message | F12: UI / Usability | G12: On login page, after a login error | H12: 1. Click the X on the red error banner. | I12: Error message closes; form ready for a new attempt | J12: Low | K12: Passed
A13: PRODUCT LISTING
A14: TC-010 | B14: Product Listing | C14: Products Page | D14: Browse | E14: Products page loads all items | F14: Functional | G14: Logged in as standard_user | H14: 1. Observe the Products page | I14: All 6 products shown, each with image, name, description, price, 'Add to cart' button | J14: High | K14: Passed
A15: TC-011 | B15: Product Listing | C15: Products Page | D15: Navigate | E15: Product image links to detail page | F15: Functional | G15: Logged in as standard_user | H15: 1. Click a product's image or name | I15: Redirected to product detail page with matching name, description, price, image, and 'Back to products' link | J15: Medium | K15: Passed
A16: TC-012 | B16: Product Listing | C16: Products Page | D16: Sort | E16: Sort: Name (A to Z) | F16: Functional | G16: Logged in as standard_user | H16: 1. Click the product sort dropdown 2. Select 'Name (A to Z)' | I16: Products reordered alphabetically ascending by name | J16: Medium | K16: Passed
A17: TC-013 | B17: Product Listing | C17: Products Page | D17: Sort | E17: Sort: Name (Z to A) | F17: Functional | G17: Logged in as standard_user | H17: 1. Click the product sort dropdown 2. Select 'Name (Z to A)' | I17: Products reordered alphabetically descending by name | J17: Medium | K17: Passed
A18: TC-014 | B18: Product Listing | C18: Products Page | D18: Sort | E18: Sort: Price (low to high) | F18: Functional | G18: Logged in as standard_user | H18: 1. Open sort dropdown 2. Select 'Price (low to high)' | I18: Products reordered by ascending price | J18: Medium | K18: Passed
A19: TC-015 | B19: Product Listing | C19: Products Page | D19: Sort | E19: Sort: Price (high to low) | F19: Functional | G19: Logged in as standard_user | H19: 1. Open sort dropdown 2. Select 'Price (high to low)' | I19: Products reordered by descending price | J19: Medium | K19: Passed
A20: TC-016 | B20: Product Listing | C20: Products Page | D20: Sort | E20: Sorting with problem_user | F20: Bug validation | G20: Logged in as problem_user | H20: 1. Repeat TC-012 to TC-015 | I20: Compare against standard_user results; document any case where sorting does not reorder products. | J20: Medium | K20: Passed
A21: SHOPPING CART
A22: TC-017 | B22: Shopping Cart | C22: Products Page | D22: Add to cart | E22: Add single item to cart | F22: Functional | G22: Logged in as standard_user, on Products page | H22: 1. Click 'Add to cart' on one product | I22: Button changes to 'Remove'; cart badge shows '1' | J22: High | K22: Passed
A23: TC-018 | B23: Shopping Cart | C23: Products Page | D23: Add to cart | E23: Add multiple items to cart | F23: Functional | G23: Logged in as standard_user, on Products page | H23: 1. Click 'Add to cart' on 3 different products | I23: Cart badge updates to '3'; all three buttons show 'Remove' | J23: High | K23: Passed
A24: TC-019 | B24: Shopping Cart | C24: Products Page | D24: Remove from cart | E24: Remove item from Products page | F24: Functional | G24: Logged in as standard_user; At least one item in cart | H24: 1. Click 'Remove' on an item already in the cart | I24: Button reverts to 'Add to cart'; badge count decreases by 1 (or disappears if cart is empty) | J24: High | K24: Passed
A25: TC-020 | B25: Shopping Cart | C25: Cart Page | D25: View cart | E25: View cart contents | F25: Functional | G25: Logged in as standard_user; At least one item in cart | H25: 1. Click the cart icon | I25: Cart page opens, listing correct item(s) with name, price, and quantity | J25: High | K25: Passed
A26: TC-021 | B26: Shopping Cart | C26: Cart Page | D26: Remove from cart | E26: Remove item from Cart page | F26: Functional | G26: Logged in as standard_user; On Cart page, with items present | H26: 1. Click 'Remove' next to an item | I26: Item disappears from cart list; badge count updates accordingly | J26: Medium | K26: Passed
A27: TC-022 | B27: Shopping Cart | C27: Cart Page | D27: Navigate | E27: Continue shopping | F27: Functional | G27: Logged in as standard_user; On Cart page | H27: 1. Click 'Continue Shopping' | I27: User returned to Products page; cart contents unchanged | J27: Low | K27: Passed
A28: TC-023 | B28: Shopping Cart | C28: Cart Page | D28: Navigate | E28: Cart persists across pages | F28: Functional | G28: Logged in as standard_user; tem(s) in cart | H28: 1. Add an item to cart 2. Navigate to a product detail page and back | I28: Cart badge count remains the same; item still present when cart is opened | J28: Medium | K28: Passed
A29: TC-024 | B29: Shopping Cart | C29: Cart Page | D29: Checkout | E29: Checkout button on empty cart | F29: Negative | G29: Logged in as standard_user; Cart is empty | H29: 1. Go to Cart page 2. Click Checkout | I29: Checkout' button present but leads to an empty order; no items listed. Document actual behavior | J29: Low | K29: Failed
A30: CHECKOUT FLOW
A31: TC-025 | B31: Checkout Flow | C31: Checkout: Your Information | D31: Fill form | E31: Complete checkout with valid data | F31: Functional | G31: Logged in as standard_user; At least one item in cart | H31: 1. Cart -> Checkout. 2. Fill First Name, Last Name, Zip/Postal Code 3. Click Continue | I31: User reaches Checkout Overview page with item(s) and price breakdown (subtotal, tax, total) | J31: High | K31: Passed
A32: TC-026 | B32: Checkout Flow | C32: Checkout: Your Information | D32: Fill form | E32: Missing first name | F32: Negative | G32: Logged in as standard_user; On Checkout: Your Information page | H32: 1. Leave First Name blank; fill other fields 2. Click Continue | I32: Error: 'Error: First Name is required' | J32: Medium | K32: Passed
A33: TC-027 | B33: Checkout Flow | C33: Checkout: Your Information | D33: Fill form | E33: Missing last name | F33: Negative | G33: Logged in as standard_user; On Checkout: Your Information page | H33: 1. Leave Last Name blank; fill other fields. 2. Click Continue | I33: Error: 'Error: Last Name is required' | J33: Medium | K33: Passed
A34: TC-028 | B34: Checkout Flow | C34: Checkout: Your Information | D34: Fill form | E34: Missing postal code | F34: Negative | G34: Logged in as standard_user; On Checkout: Your Information page | H34: 1. Leave Zip/Postal Code blank; fill other fields 2. Click Continue | I34: Error: 'Error: Postal Code is required' | J34: Medium | K34: Passed
A35: TC-029 | B35: Checkout Flow | C35: Checkout: Your Information | D35: Cancel | E35: Cancel checkout from info step | F35: Functional | G35: Logged in as standard_user; On Checkout: Your Information page | H35: 1. Click Cancel | I35: User returned to Cart page; cart contents unchanged | J35: Low | K35: Passed
A36: TC-030 | B36: Checkout Flow | C36: Checkout Overview | D36: Verify totals | E36: Order total calculation | F36: Functional | G36: Logged in as standard_user; On Checkout Overview page | H36: 1. Note item price(s) shown 2. Verify Item total, Tax, and Total | I36: Item total equals sum of item prices; Total equals Item total + Tax, matching displayed values | J36: High | K36: Passed
A37: TC-031 | B37: Checkout Flow | C37: Checkout Overview | D37: Cancel | E37: Cancel checkout from overview step | F37: Functional | G37: Logged in as standard_user; On Checkout Overview page | H37: 1. Click Cancel | I37: User returned to Products page; cart is preserved (not cleared) | J37: Low | K37: Passed
A38: TC-032 | B38: Checkout Flow | C38: Checkout Overview | D38: Finish | E38: Finish checkout | F38: Functional | G38: Logged in as standard_user; On Checkout Overview page | H38: 1. Click Finish | I38: Checkout: Complete!' page shown with confirmation message and 'Back Home' button and 'Generate PDF order' button | J38: High | K38: Passed
A39: TC-033 | B39: Checkout Flow | C39: Checkout Complete | D39: Verify cart | E39: Cart cleared after successful order | F39: Functional | G39: Logged in as standard_user; Just completed checkout (TC-032) | H39: 1. Click 'Back Home' 2. Check the cart icon | I39: Cart badge is gone (0 items); cart is empty when opened | J39: Medium | K39: Passed
A40: LOGOUT & SESSION
...

Sheet Summary
A1: ServeRest API – Test Execution Summary
A2: Module | B2: Total TCs | C2: Not Executed | D2: Passed | E2: Failed | F2: Pass Rate
A3: LOGIN | B3: =COUNTIF('Test Cases'!$B:$B,A3) -> 9 | C3: =COUNTIFS('Test Cases'!$B:$B,A3,'Test Cases'!$K:$K,"Not Executed") -> 0 | D3: =COUNTIFS('Test Cases'!$B:$B,A3,'Test Cases'!$K:$K,"Passed") -> 9 | E3: =COUNTIFS('Test Cases'!$B:$B,A3,'Test Cases'!$K:$K,"Failed") -> 0 | F3: =IF(B3=0,"-",D3/B3) -> 1
A4: Users | B4: =COUNTIF('Test Cases'!$B:$B,A4) -> 0 | C4: =COUNTIFS('Test Cases'!$B:$B,A4,'Test Cases'!$K:$K,"Not Executed") -> 0 | D4: =COUNTIFS('Test Cases'!$B:$B,A4,'Test Cases'!$K:$K,"Passed") -> 0 | E4: =COUNTIFS('Test Cases'!$B:$B,A4,'Test Cases'!$K:$K,"Failed") -> 0 | F4: =IF(B4=0,"-",D4/B4) -> -
A5: Products | B5: =COUNTIF('Test Cases'!$B:$B,A5) -> 0 | C5: =COUNTIFS('Test Cases'!$B:$B,A5,'Test Cases'!$K:$K,"Not Executed") -> 0 | D5: =COUNTIFS('Test Cases'!$B:$B,A5,'Test Cases'!$K:$K,"Passed") -> 0 | E5: =COUNTIFS('Test Cases'!$B:$B,A5,'Test Cases'!$K:$K,"Failed") -> 0 | F5: =IF(B5=0,"-",D5/B5) -> -
A6: Carts | B6: =COUNTIF('Test Cases'!$B:$B,A6) -> 0 | C6: =COUNTIFS('Test Cases'!$B:$B,A6,'Test Cases'!$K:$K,"Not Executed") -> 0 | D6: =COUNTIFS('Test Cases'!$B:$B,A6,'Test Cases'!$K:$K,"Passed") -> 0 | E6: =COUNTIFS('Test Cases'!$B:$B,A6,'Test Cases'!$K:$K,"Failed") -> 0 | F6: =IF(B6=0,"-",D6/B6) -> -
A7: TOTAL | B7: =SUM(B3:B6) -> 9 | C7: =SUM(C3:C6) -> 0 | D7: =SUM(D3:D6) -> 9 | E7: =SUM(E3:E6) -> 0 | F7: =IF(B7=0,"-",D7/B7) -> 1
A9: STATUS LEGEND
A10: Not Executed | B10: Tests not yet run
A11: Passed | B11: Test passed as expected
A12: Failed | B12: Test failed – bug to be logged
A13: Blocked | B13: Blocked by dependency or environment
